{
  "timestamp": "2025-09-30T07:55:29.581289",
  "success_rate": 0.0,
  "total_passed": 0,
  "total_tests": 23,
  "detailed_results": [
    {
      "test": "Phase 6 - Zero Trust Access Evaluation",
      "success": false,
      "response_time": null,
      "details": "HTTPConnectionPool(host='127.0.0.1', port=5001): Max retries exceeded with url: /api/security/access/evaluate (Caused by NewConnectionError('<urllib3.connection.HTTPConnection object at 0x7fdd8181da30>: Failed to establish a new connection: [Errno 111] Connection refused'))",
      "timestamp": "2025-09-30T07:55:29.559637"
    },
    {
      "test": "Phase 6 - Security Event Review",
      "success": false,
      "response_time": null,
      "details": "HTTPConnectionPool(host='127.0.0.1', port=5001): Max retries exceeded with url: /api/security/events/review (Caused by NewConnectionError('<urllib3.connection.HTTPConnection object at 0x7fdd8181de80>: Failed to establish a new connection: [Errno 111] Connection refused'))",
      "timestamp": "2025-09-30T07:55:29.560486"
    },
    {
      "test": "Phase 6 - HITL Security Analysis",
      "success": false,
      "response_time": null,
      "details": "HTTPConnectionPool(host='127.0.0.1', port=5001): Max retries exceeded with url: /api/security/hitl/submit (Caused by NewConnectionError('<urllib3.connection.HTTPConnection object at 0x7fdd8181e5d0>: Failed to establish a new connection: [Errno 111] Connection refused'))",
      "timestamp": "2025-09-30T07:55:29.561273"
    },
    {
      "test": "Phase 6 - Security Audit",
      "success": false,
      "response_time": null,
      "details": "HTTPConnectionPool(host='127.0.0.1', port=5001): Max retries exceeded with url: /api/security/audit (Caused by NewConnectionError('<urllib3.connection.HTTPConnection object at 0x7fdd8181ed20>: Failed to establish a new connection: [Errno 111] Connection refused'))",
      "timestamp": "2025-09-30T07:55:29.561954"
    },
    {
      "test": "Phase 6 - Pending Security Reviews",
      "success": false,
      "response_time": null,
      "details": "HTTPConnectionPool(host='127.0.0.1', port=5001): Max retries exceeded with url: /api/security/reviews/pending (Caused by NewConnectionError('<urllib3.connection.HTTPConnection object at 0x7fdd8181f470>: Failed to establish a new connection: [Errno 111] Connection refused'))",
      "timestamp": "2025-09-30T07:55:29.562646"
    },
    {
      "test": "Phase 7 - System Status",
      "success": false,
      "response_time": null,
      "details": "HTTPConnectionPool(host='127.0.0.1', port=5001): Max retries exceeded with url: /api/phase7/status (Caused by NewConnectionError('<urllib3.connection.HTTPConnection object at 0x7fdd8181f3e0>: Failed to establish a new connection: [Errno 111] Connection refused'))",
      "timestamp": "2025-09-30T07:55:29.563585"
    },
    {
      "test": "Phase 7 - Pending Approvals",
      "success": false,
      "response_time": null,
      "details": "HTTPConnectionPool(host='127.0.0.1', port=5001): Max retries exceeded with url: /api/phase7/approvals/pending (Caused by NewConnectionError('<urllib3.connection.HTTPConnection object at 0x7fdd8181ecf0>: Failed to establish a new connection: [Errno 111] Connection refused'))",
      "timestamp": "2025-09-30T07:55:29.564247"
    },
    {
      "test": "Phase 7 - Beta Candidates",
      "success": false,
      "response_time": null,
      "details": "HTTPConnectionPool(host='127.0.0.1', port=5001): Max retries exceeded with url: /api/phase7/beta/candidates (Caused by NewConnectionError('<urllib3.connection.HTTPConnection object at 0x7fdd8181e780>: Failed to establish a new connection: [Errno 111] Connection refused'))",
      "timestamp": "2025-09-30T07:55:29.564861"
    },
    {
      "test": "Phase 7 - Growth Metrics",
      "success": false,
      "response_time": null,
      "details": "HTTPConnectionPool(host='127.0.0.1', port=5001): Max retries exceeded with url: /api/phase7/growth/metrics (Caused by NewConnectionError('<urllib3.connection.HTTPConnection object at 0x7fdd8181dc70>: Failed to establish a new connection: [Errno 111] Connection refused'))",
      "timestamp": "2025-09-30T07:55:29.565505"
    },
    {
      "test": "Phase 7 - Operations Metrics",
      "success": false,
      "response_time": null,
      "details": "HTTPConnectionPool(host='127.0.0.1', port=5001): Max retries exceeded with url: /api/phase7/ops/metrics (Caused by NewConnectionError('<urllib3.connection.HTTPConnection object at 0x7fdd818483b0>: Failed to establish a new connection: [Errno 111] Connection refused'))",
      "timestamp": "2025-09-30T07:55:29.566176"
    },
    {
      "test": "Phase 7 - Monitoring Dashboard",
      "success": false,
      "response_time": null,
      "details": "HTTPConnectionPool(host='127.0.0.1', port=5001): Max retries exceeded with url: /api/phase7/monitoring/dashboard (Caused by NewConnectionError('<urllib3.connection.HTTPConnection object at 0x7fdd81848c50>: Failed to establish a new connection: [Errno 111] Connection refused'))",
      "timestamp": "2025-09-30T07:55:29.567285"
    },
    {
      "test": "Phase 7 - Resilience Metrics",
      "success": false,
      "response_time": null,
      "details": "HTTPConnectionPool(host='127.0.0.1', port=5001): Max retries exceeded with url: /api/phase7/resilience/metrics (Caused by NewConnectionError('<urllib3.connection.HTTPConnection object at 0x7fdd8181e4b0>: Failed to establish a new connection: [Errno 111] Connection refused'))",
      "timestamp": "2025-09-30T07:55:29.568778"
    },
    {
      "test": "Phase 7 - Environment Validation",
      "success": false,
      "response_time": null,
      "details": "HTTPConnectionPool(host='127.0.0.1', port=5001): Max retries exceeded with url: /api/phase7/environment/validate (Caused by NewConnectionError('<urllib3.connection.HTTPConnection object at 0x7fdd8181ea20>: Failed to establish a new connection: [Errno 111] Connection refused'))",
      "timestamp": "2025-09-30T07:55:29.569858"
    },
    {
      "test": "Phase 8 - Dashboard Layouts",
      "success": false,
      "response_time": null,
      "details": "HTTPConnectionPool(host='127.0.0.1', port=5001): Max retries exceeded with url: /api/dashboard/layouts (Caused by NewConnectionError('<urllib3.connection.HTTPConnection object at 0x7fdd8181eae0>: Failed to establish a new connection: [Errno 111] Connection refused'))",
      "timestamp": "2025-09-30T07:55:29.570917"
    },
    {
      "test": "Phase 8 - Available Widgets",
      "success": false,
      "response_time": null,
      "details": "HTTPConnectionPool(host='127.0.0.1', port=5001): Max retries exceeded with url: /api/dashboard/widgets/available (Caused by NewConnectionError('<urllib3.connection.HTTPConnection object at 0x7fdd8181f140>: Failed to establish a new connection: [Errno 111] Connection refused'))",
      "timestamp": "2025-09-30T07:55:29.572035"
    },
    {
      "test": "Phase 8 - Dashboard Data",
      "success": false,
      "response_time": null,
      "details": "HTTPConnectionPool(host='127.0.0.1', port=5001): Max retries exceeded with url: /api/dashboard/data (Caused by NewConnectionError('<urllib3.connection.HTTPConnection object at 0x7fdd81848470>: Failed to establish a new connection: [Errno 111] Connection refused'))",
      "timestamp": "2025-09-30T07:55:29.573087"
    },
    {
      "test": "Phase 8 - Report Generation",
      "success": false,
      "response_time": null,
      "details": "HTTPConnectionPool(host='127.0.0.1', port=5001): Max retries exceeded with url: /api/reports/generate (Caused by NewConnectionError('<urllib3.connection.HTTPConnection object at 0x7fdd81849460>: Failed to establish a new connection: [Errno 111] Connection refused'))",
      "timestamp": "2025-09-30T07:55:29.574123"
    },
    {
      "test": "Phase 8 - Report Templates",
      "success": false,
      "response_time": null,
      "details": "HTTPConnectionPool(host='127.0.0.1', port=5001): Max retries exceeded with url: /api/reports/templates (Caused by NewConnectionError('<urllib3.connection.HTTPConnection object at 0x7fdd8181f590>: Failed to establish a new connection: [Errno 111] Connection refused'))",
      "timestamp": "2025-09-30T07:55:29.575057"
    },
    {
      "test": "Phase 8 - Report History",
      "success": false,
      "response_time": null,
      "details": "HTTPConnectionPool(host='127.0.0.1', port=5001): Max retries exceeded with url: /api/reports/history (Caused by NewConnectionError('<urllib3.connection.HTTPConnection object at 0x7fdd8181e150>: Failed to establish a new connection: [Errno 111] Connection refused'))",
      "timestamp": "2025-09-30T07:55:29.576110"
    },
    {
      "test": "Phase 8 - Custom Dashboard Creation",
      "success": false,
      "response_time": null,
      "details": "HTTPConnectionPool(host='127.0.0.1', port=5001): Max retries exceeded with url: /api/dashboard/layouts (Caused by NewConnectionError('<urllib3.connection.HTTPConnection object at 0x7fdd8181dc10>: Failed to establish a new connection: [Errno 111] Connection refused'))",
      "timestamp": "2025-09-30T07:55:29.577043"
    },
    {
      "test": "Integration - Security + Performance Monitoring",
      "success": false,
      "response_time": null,
      "details": "HTTPConnectionPool(host='127.0.0.1', port=5001): Max retries exceeded with url: /api/security/events/review (Caused by NewConnectionError('<urllib3.connection.HTTPConnection object at 0x7fdd81848650>: Failed to establish a new connection: [Errno 111] Connection refused'))",
      "timestamp": "2025-09-30T07:55:29.578013"
    },
    {
      "test": "Integration - Security Dashboard Data",
      "success": false,
      "response_time": null,
      "details": "HTTPConnectionPool(host='127.0.0.1', port=5001): Max retries exceeded with url: /api/dashboard/data (Caused by NewConnectionError('<urllib3.connection.HTTPConnection object at 0x7fdd818495e0>: Failed to establish a new connection: [Errno 111] Connection refused'))",
      "timestamp": "2025-09-30T07:55:29.578877"
    },
    {
      "test": "Integration - Growth + Security Report",
      "success": false,
      "response_time": null,
      "details": "HTTPConnectionPool(host='127.0.0.1', port=5001): Max retries exceeded with url: /api/reports/generate (Caused by NewConnectionError('<urllib3.connection.HTTPConnection object at 0x7fdd81849e50>: Failed to establish a new connection: [Errno 111] Connection refused'))",
      "timestamp": "2025-09-30T07:55:29.580398"
    }
  ]
}