# Testing Sentry Trace ID in MorningAI

Sentry is a powerful error tracking tool that helps developers monitor and fix crashes in real-time. In the context of MorningAI, Sentry is integrated to enhance the reliability of the platform by quickly identifying, tracking, and resolving issues. A key component of Sentry's utility is the `trace_id`, which uniquely identifies a set of events or transactions across the system. This FAQ aims to guide developers on how to test and utilize Sentry's `trace_id` within the MorningAI platform.

## Understanding Trace ID

The `trace_id` is a unique identifier used by Sentry to link together a series of events or transactions. This allows developers to trace the path of an issue through the system, understanding its impact and root cause.

### How Trace ID Works in MorningAI

In MorningAI, each task or process that might fail or produce an error generates a `trace_id`. This ID can be used to track the specific flow of execution that led to an error, making it easier to diagnose and resolve issues.

## Implementing and Testing Trace ID

To implement and test Sentry's `trace_id` functionality in MorningAI, follow these steps:

### Step 1: Configuration

Ensure Sentry is configured correctly in your environment. In your Flask app setup (typically found in `app/__init__.py`), ensure you have something like:

```python
from sentry_sdk import init
from sentry_sdk.integrations.flask import FlaskIntegration

sentry_sdk.init(
    dsn="your_sentry_dsn_here",
    integrations=[FlaskIntegration()]
)
```

Replace `"your_sentry_dsn_here"` with your actual Sentry DSN.

### Step 2: Generating and Logging Trace ID

When initializing a task or process that should be tracked, generate a `trace_id`:

```python
import uuid
from sentry_sdk import set_context

def start_task():
    trace_id = uuid.uuid4()
    set_context("trace", {"id": str(trace_id)})
    # Proceed with your task logic
```

### Step 3: Testing

To test, intentionally produce an error in a task where you've implemented the trace ID logic:

```python
def start_task():
    trace_id = uuid.uuid4()
    set_context("trace", {"id": str(trace_id)})
    # Intentional error for testing
    raise ValueError("This is a test error")
```

Check your Sentry dashboard for the reported error. You should be able to find the `trace_id` associated with this error in the event's details.

## Related Documentation Links

- [Sentry Documentation](https://docs.sentry.io)
- [Python SDK for Sentry](https://docs.sentry.io/platforms/python/)

## Common Troubleshooting Tips

- **Missing Errors**: If errors are not appearing in Sentry, check that your DSN is correctly configured and that your internet connection allows communication with Sentry's servers.
- **Trace ID Not Found**: Ensure that `set_context` is being called before any potential error or exception could occur in your code path.
- **Performance Issues**: Overuse of tracing or generating excessive logs can impact application performance. Use trace IDs judiciously.

Remember, proper integration and testing of Sentry's trace ID functionality can significantly improve the maintainability and reliability of MorningAI by providing detailed insights into errors and system behavior.

---
Generated by MorningAI Orchestrator using GPT-4

---

**Metadata**:
- Task: Test Sentry trace_id
- Trace ID: `5308d24e-ace7-4eaf-9f30-4efc06eac39f`
- Generated by: MorningAI Orchestrator using gpt-4-turbo-preview
- Repository: RC918/morningai
